<?xml version="1.0"?>
<robot name="agrolab">
  
    <link name="base_link">
      <visual>
        <origin rpy="0 0 0" xyz="0 0 0"/>
        <geometry>
          <mesh filename="package://agrolab_description/meshes/case.dae" scale="1 1 1"/>
        </geometry>
      </visual>
      <collision>
        <geometry>
          <mesh filename="package://agrolab_description/meshes/case.stl" scale="1 1 1"/>
        </geometry>
        <origin rpy="0 0 0" xyz="0 0 0"/>
      </collision>
      <inertial>
      <mass value="7"/>
      <inertia ixx="0.0" ixy="0.0" ixz="0.0" iyy="0.0" iyz="0.0" izz="0.0"/>
    </inertial>
    </link>

    <link name="Light">
      <visual>
        <origin rpy="0 0 0" xyz="0 0 0"/>
        <geometry>
          <mesh filename="package://agrolab_description/meshes/light.dae" scale="1 1 1"/>
        </geometry>
      </visual>
      <collision>
        <geometry>
          <mesh filename="package://agrolab_description/meshes/light.stl" scale="1 1 1"/>
        </geometry>
        <origin rpy="0 0 0" xyz="0 0 0"/>
      </collision>
    <inertial>
      <mass value="0.1"/>
      <inertia ixx="0.0" ixy="0.0" ixz="0.0" iyy="0.0" iyz="0.0" izz="0.0"/>
    </inertial>
    </link>

    <link name="Water_tank">
      <visual>
        <origin rpy="0 0 0" xyz="0 0 0"/>
        <geometry>
          <mesh filename="package://agrolab_description/meshes/water_tank.dae" scale="1 1 1"/>
        </geometry>
      </visual>
      <collision>
        <geometry>
          <mesh filename="package://agrolab_description/meshes/water_tank.stl" scale="1 1 1"/>
        </geometry>
        <origin rpy="0 0 0" xyz="0 0 0"/>
      </collision>
     <inertial>
      <mass value="0.5"/>
       <inertia ixx="0.0" ixy="0.0" ixz="0.0" iyy="0.0" iyz="0.0" izz="0.0"/>
    </inertial>
    </link>
    
    <link name="Stand">
      <visual>
        <origin rpy="0 0 0" xyz="0 0 0"/>
        <geometry>
          <mesh filename="package://agrolab_description/meshes/stand.dae" scale="1 1 1"/>
        </geometry>
      </visual>
      <collision>
        <geometry>
          <mesh filename="package://agrolab_description/meshes/stand.stl" scale="1 1 1"/>
        </geometry>
        <origin rpy="0 0 0" xyz="0 0 0"/>
      </collision>
    <inertial>
      <mass value="0.01"/>
       <inertia ixx="0.0" ixy="0.0" ixz="0.0" iyy="0.0" iyz="0.0" izz="0.0"/>
    </inertial>
    </link>  
          
    <link name="X">
      <visual>
        <origin rpy="0 0 0" xyz="0 0 0"/>
        <geometry>
          <mesh filename="package://agrolab_description/meshes/X.dae" scale="1 1 1"/>
        </geometry>
      </visual>
      <collision>
        <geometry>
          <mesh filename="package://agrolab_description/meshes/X.stl" scale="1 1 1"/>
        </geometry>
        <origin rpy="0 0 0" xyz="0 0 0"/>
      </collision>
    <inertial>
      <mass value="1"/>
       <inertia ixx="0.0" ixy="0.0" ixz="0.0" iyy="0.0" iyz="0.0" izz="0.0"/>
    </inertial>
    </link>

    <link name="Y">
      <visual>
        <origin rpy="0 0 0" xyz="0 -0.01 0"/>
        <geometry>
          <mesh filename="package://agrolab_description/meshes/Y.dae" scale="1 1 1"/>
        </geometry>
      </visual>
      <collision>
        <geometry>
          <mesh filename="package://agrolab_description/meshes/Y.stl" scale="1 1 1"/>
        </geometry>
        <origin rpy="0 0 0" xyz="0 -0.01 0"/>
      </collision>
    <inertial>
      <mass value="1.8543"/>
       <inertia ixx="0.0" ixy="0.0" ixz="0.0" iyy="0.0" iyz="0.0" izz="0.0"/>
    </inertial>
    </link>
    
    <link name="Z">
      <visual>
        <origin rpy="0 0 0" xyz="0 -0.01 0.02"/>
        <geometry>
          <mesh filename="package://agrolab_description/meshes/Z.dae" scale="1 1 1"/>
        </geometry>
      </visual>
      <collision>
        <geometry>
          <mesh filename="package://agrolab_description/meshes/Z.stl" scale="1 1 1"/>
        </geometry>
        <origin rpy="0 0 0" xyz="0 -0.01 0.02"/>
      </collision>
    <inertial>
      <mass value="0.337"/>
       <inertia ixx="0.0" ixy="0.0" ixz="0.0" iyy="0.0" iyz="0.0" izz="0.0"/>
    </inertial>
    </link>      

    <joint name="base_link_to_light" type="fixed">
    <parent link="base_link"/>
    <child link="Light"/>
  </joint>
  
    <joint name="base_link_to_water_tank" type="fixed">
    <parent link="base_link"/>
    <child link="Water_tank"/>
  </joint>  
  
    <joint name="base_link_to_stand" type="fixed">
    <parent link="base_link"/>
    <child link="Stand"/>
  </joint>  
        
    <joint name="base_link_to_X" type="prismatic">
    <parent link="base_link"/>
    <child link="X"/>
    <axis xyz="1 0 0" />
    <limit effort="10000" lower="0" upper="0.43" velocity="1" />
  </joint>
  
    <joint name="X_to_Y" type="prismatic">
    <parent link="X"/>
    <child link="Y"/>
    <axis xyz="0 1 0" />
    <limit effort="10000" lower="0" upper="0.54" velocity="1" />
  </joint>   
      <joint name="Y_to_Z" type="prismatic">
    <parent link="Y"/>
    <child link="Z"/>
    <axis xyz="0 0 -1" />
    <limit effort="10000" lower="0" upper="0.2" velocity="1" />
  </joint>       
</robot>
